Workbook

Sheet 2025 입학생 3개년 교육과정(2학년)
A1: 2025학년도 입학생 3개년 교육과정 편성표(2학년)
A2: 명신고등학교(공립)
A3: 구 분 | B3: 교과(군) | C3: 과목 유형 | D3: 과목 | E3: 기본 학점 | F3: 운영 학점 | G3: 1학년 | I3: 2학년 | K3: 3학년 | M3: 편성학점 합 | O3: 성적처리 유형
G4: 1학기 | H4: 2학기 | I4: 1학기 | J4: 2학기 | K4: 1학기 | L4: 2학기 | M4: 교과(군) | N4: 선택군
A5: 학 교 지 정 과 목 | B5: 국어 | C5: =VLOOKUP(D5,[1]숨김!$B$3:$E$300,2,0) -> 공통 | D5: 공통국어1 | E5: =VLOOKUP(D5,[1]숨김!$B$3:$E$300,3,0) -> 4 | F5: 3 | G5: 3 | M5: =SUM(G5:L9) -> 17 | N5: =SUM(M5,M10,M15) -> 52 | O5: =VLOOKUP(D5,[1]숨김!$B$3:$E$300,4,0) -> 성취도 5단계+석차등급O
C6: =VLOOKUP(D6,[1]숨김!$B$3:$E$300,2,0) -> 공통 | D6: 공통국어2 | E6: =VLOOKUP(D6,[1]숨김!$B$3:$E$300,3,0) -> 4 | F6: 3 | H6: 3 | O6: =VLOOKUP(D6,[1]숨김!$B$3:$E$300,4,0) -> 성취도 5단계+석차등급O
C7: 일반 | D7: 문학 | E7: 4 | F7: 4 | I7: 4 | O7: =VLOOKUP(D7,[1]숨김!$B$3:$E$300,4,0) -> 성취도 5단계+석차등급O
C8: 일반 | D8: 화법과 언어 | E8: 4 | F8: 3 | J8: 3 | O8: 성취도 5단계+석차등급O
C9: 일반 | D9: 독서와 작문 | E9: 4 | F9: 4 | K9: 4 | O9: =VLOOKUP(D9,[1]숨김!$B$3:$E$300,4,0) -> 성취도 5단계+석차등급O
B10: 수학 | C10: =VLOOKUP(D10,[1]숨김!$B$3:$E$300,2,0) -> 공통 | D10: 공통수학1 | E10: =VLOOKUP(D10,[1]숨김!$B$3:$E$300,3,0) -> 4 | F10: 3 | G10: 3 | M10: =SUM(G10:L14) -> 17 | O10: =VLOOKUP(D10,[1]숨김!$B$3:$E$300,4,0) -> 성취도 5단계+석차등급O
C11: =VLOOKUP(D11,[1]숨김!$B$3:$E$300,2,0) -> 공통 | D11: 공통수학2 | E11: =VLOOKUP(D11,[1]숨김!$B$3:$E$300,3,0) -> 4 | F11: 3 | H11: 3 | O11: =VLOOKUP(D11,[1]숨김!$B$3:$E$300,4,0) -> 성취도 5단계+석차등급O
C12: 일반 | D12: 대수 | E12: 4 | F12: 3 | I12: 3 | O12: =VLOOKUP(D12,[1]숨김!$B$3:$E$300,4,0) -> 성취도 5단계+석차등급O
C13: 일반 | D13: 미적분Ⅰ | E13: 4 | F13: 4 | J13: 4 | O13: 성취도 5단계+석차등급O
C14: 일반 | D14: 확률과 통계 | E14: 4 | F14: 4 | K14: 4 | O14: =VLOOKUP(D14,[1]숨김!$B$3:$E$300,4,0) -> 성취도 5단계+석차등급O
B15: 영어 | C15: =VLOOKUP(D15,[1]숨김!$B$3:$E$300,2,0) -> 공통 | D15: 공통영어1 | E15: =VLOOKUP(D15,[1]숨김!$B$3:$E$300,3,0) -> 4 | F15: 3 | G15: 3 | M15: =SUM(G15:L19) -> 18 | O15: =VLOOKUP(D15,[1]숨김!$B$3:$E$300,4,0) -> 성취도 5단계+석차등급O
C16: =VLOOKUP(D16,[1]숨김!$B$3:$E$300,2,0) -> 공통 | D16: 공통영어2 | E16: =VLOOKUP(D16,[1]숨김!$B$3:$E$300,3,0) -> 4 | F16: 3 | H16: 3 | O16: =VLOOKUP(D16,[1]숨김!$B$3:$E$300,4,0) -> 성취도 5단계+석차등급O
C17: 일반 | D17: 영어Ⅰ | E17: 4 | F17: 4 | I17: 4 | O17: 성취도 5단계+석차등급O
C18: 일반 | D18: 영어Ⅱ | E18: 4 | F18: 4 | J18: 4 | O18: 성취도 5단계+석차등급O
C19: 일반 | D19: 영어 독해와 작문 | E19: 4 | F19: 4 | K19: 4 | O19: =VLOOKUP(D19,[1]숨김!$B$3:$E$300,4,0) -> 성취도 5단계+석차등급O
B20: 사회 | C20: =VLOOKUP(D20,[1]숨김!$B$3:$E$300,2,0) -> 공통 | D20: 한국사1 | E20: =VLOOKUP(D20,[1]숨김!$B$3:$E$300,3,0) -> 3 | F20: 3 | G20: 3 | M20: =SUM(G20:L21) -> 6 | O20: =VLOOKUP(D20,[1]숨김!$B$3:$E$300,4,0) -> 성취도 5단계+석차등급O
C21: =VLOOKUP(D21,[1]숨김!$B$3:$E$300,2,0) -> 공통 | D21: 한국사2 | E21: =VLOOKUP(D21,[1]숨김!$B$3:$E$300,3,0) -> 3 | F21: 3 | H21: 3 | O21: =VLOOKUP(D21,[1]숨김!$B$3:$E$300,4,0) -> 성취도 5단계+석차등급O
C22: =VLOOKUP(D22,[1]숨김!$B$3:$E$300,2,0) -> 공통 | D22: 통합사회1 | E22: =VLOOKUP(D22,[1]숨김!$B$3:$E$300,3,0) -> 4 | F22: 3 | G22: 3 | M22: =SUM(G22:L23) -> 6 | O22: =VLOOKUP(D22,[1]숨김!$B$3:$E$300,4,0) -> 성취도 5단계+석차등급O
C23: =VLOOKUP(D23,[1]숨김!$B$3:$E$300,2,0) -> 공통 | D23: 통합사회2 | E23: =VLOOKUP(D23,[1]숨김!$B$3:$E$300,3,0) -> 4 | F23: 3 | H23: 3 | O23: =VLOOKUP(D23,[1]숨김!$B$3:$E$300,4,0) -> 성취도 5단계+석차등급O
B24: 과학 | C24: =VLOOKUP(D24,[1]숨김!$B$3:$E$300,2,0) -> 공통 | D24: 통합과학1 | E24: =VLOOKUP(D24,[1]숨김!$B$3:$E$300,3,0) -> 4 | F24: 3 | G24: 3 | M24: =SUM(G24:L27) -> 8 | O24: =VLOOKUP(D24,[1]숨김!$B$3:$E$300,4,0) -> 성취도 5단계+석차등급O
C25: =VLOOKUP(D25,[1]숨김!$B$3:$E$300,2,0) -> 공통 | D25: 통합과학2 | E25: =VLOOKUP(D25,[1]숨김!$B$3:$E$300,3,0) -> 4 | F25: 3 | H25: 3 | O25: =VLOOKUP(D25,[1]숨김!$B$3:$E$300,4,0) -> 성취도 5단계+석차등급O
C26: =VLOOKUP(D26,[1]숨김!$B$3:$E$300,2,0) -> 공통 | D26: 과학탐구실험1 | E26: =VLOOKUP(D26,[1]숨김!$B$3:$E$300,3,0) -> 1 | F26: 1 | G26: 1 | O26: =VLOOKUP(D26,[1]숨김!$B$3:$E$300,4,0) -> 성취도 3단계
C27: =VLOOKUP(D27,[1]숨김!$B$3:$E$300,2,0) -> 공통 | D27: 과학탐구실험2 | E27: =VLOOKUP(D27,[1]숨김!$B$3:$E$300,3,0) -> 1 | F27: 1 | H27: 1 | O27: =VLOOKUP(D27,[1]숨김!$B$3:$E$300,4,0) -> 성취도 3단계
B28: 체육 | C28: 일반 | D28: 체육1 | E28: 3 | F28: 2 | G28: 2 | M28: =SUM(G28:L33) -> 10 | O28: =VLOOKUP(D28,[1]숨김!$B$3:$E$300,4,0) -> 성취도 3단계
C29: 일반 | D29: 체육2 | E29: 3 | F29: 2 | H29: 2 | O29: =VLOOKUP(D29,[1]숨김!$B$3:$E$300,4,0) -> 성취도 3단계
C30: 진로 | D30: 스포츠 문화 | E30: 2 | F30: 1 | I30: 1 | O30: =VLOOKUP(D30,[1]숨김!$B$3:$E$300,4,0) -> 성취도 3단계
C31: 진로 | D31: 스포츠 과학 | E31: 2 | F31: 1 | J31: 1 | O31: =VLOOKUP(D31,[1]숨김!$B$3:$E$300,4,0) -> 성취도 3단계
C32: 융합 | D32: 스포츠 생활1 | E32: 3 | F32: 2 | K32: 2 | O32: 성취도 3단계
C33: 융합 | D33: 스포츠 생활2 | E33: 3 | F33: 2 | L33: 2 | O33: 성취도 3단계
B34: 예술 | C34: 일반 | D34: 음악↔미술 | E34: 3 | F34: 3 | G34: 3 | H34: 3 | M34: =SUM(G34:L37) -> 10 | O34: 성취도 3단계
C35: 일반 | E35: 3 | F35: 3 | O35: 성취도 3단계
C36: 진로 | D36: 미술 창작 | E36: 3 | F36: 2 | I36: 2 | O36: 성취도 3단계
C37: 진로 | D37: 미술 감상과 비평 | E37: 3 | F37: 2 | J37: 2 | O37: =VLOOKUP(D37,[1]숨김!$B$3:$E$300,4,0) -> 성취도 3단계
B38: 정보 | C38: 일반 | D38: 한문↔정보 | E38: 4 | F38: 3 | G38: 3 | H38: 3 | M38: =G38+H38+G40+H40+L42 -> 13 | O38: 성취도 5단계+석차등급O
B39: 한문 | C39: 일반 | E39: 4 | F39: 3 | O39: 성취도 5단계+석차등급O
B40: 교양 | C40: 일반 | D40: 진로와 직업↔생태와 환경 | E40: 3 | F40: 2 | G40: 2 | H40: 2 | O40: 이수/미이수
...
